Workbook

Sheet Japan 2
A1: ลำดับ | B1: ชื่อ | C1: รายการสินค้า | D1: จำนวน | E1: ราคา/ชิ้น | F1: ราคารวม
A2: 1 | B2: Joyya | C2: birken boston mocha 42 | D2: 0 | E2: =if(C2<>"", VLOOKUP(C2,' สรุปยอด 2'!A:D,4,0),0) -> 5690 | F2: =E2*D2 -> 0
A3: 2 | B3: plearn | C3: face mask medicube ชมพู | D3: 1 | E3: =if(C3<>"", VLOOKUP(C3,' สรุปยอด 2'!A:D,4,0),0) -> 219 | F3: =E3*D3 -> 219
A4: 3 | B4: plearn | C4: kose gluta bomb ชมพู | D4: 1 | E4: =if(C4<>"", VLOOKUP(C4,' สรุปยอด 2'!A:D,4,0),0) -> 175 | F4: =E4*D4 -> 175
A5: 4 | B5: may | C5: ฮาดะทองใสแถบแดง (ขวด) | D5: 1 | E5: =if(C5<>"", VLOOKUP(C5,' สรุปยอด 2'!A:D,4,0),0) -> 275 | F5: =E5*D5 -> 275
A6: 5 | B6: sukwasa | C6: medicube pro x2 pink | D6: 1 | E6: =if(C6<>"", VLOOKUP(C6,' สรุปยอด 2'!A:D,4,0),0) -> 7490 | F6: =E6*D6 -> 7490
A7: 6 | B7: fonjinda | C7: ฮาดะทองใสแถบแดง (รีฟิล) | D7: 1 | E7: =if(C7<>"", VLOOKUP(C7,' สรุปยอด 2'!A:D,4,0),0) -> 259 | F7: =E7*D7 -> 259
A8: 7 | B8: จอมโหด | C8: ฮาดะทองใสแถบแดง (ขวด) | D8: 1 | E8: =if(C8<>"", VLOOKUP(C8,' สรุปยอด 2'!A:D,4,0),0) -> 275 | F8: =E8*D8 -> 275
A9: 8 | B9: Mt | C9: urea cream กระปุก | D9: 2 | E9: =if(C9<>"", VLOOKUP(C9,' สรุปยอด 2'!A:D,4,0),0) -> 199 | F9: =E9*D9 -> 398
A10: 9 | B10: Mt | C10: มาส์กข้าว | D10: 1 | E10: =if(C10<>"", VLOOKUP(C10,' สรุปยอด 2'!A:D,4,0),0) -> 195 | F10: =E10*D10 -> 195
A11: 10 | B11: Mt | C11: 7-11 แซนวิสส้ม | D11: 4 | E11: =if(C11<>"", VLOOKUP(C11,' สรุปยอด 2'!A:D,4,0),0) -> 85 | F11: =E11*D11 -> 340
A12: 11 | B12: Mt | C12: 7-11 ลิ้นแมวไวท์ | D12: 2 | E12: =if(C12<>"", VLOOKUP(C12,' สรุปยอด 2'!A:D,4,0),0) -> 65 | F12: =E12*D12 -> 130
A13: 12 | B13: Pomme | C13: 7-11 แซนวิสส้ม | D13: 3 | E13: =if(C13<>"", VLOOKUP(C13,' สรุปยอด 2'!A:D,4,0),0) -> 85 | F13: =E13*D13 -> 255
... A20: 19 | B20: piggy | C20: matcha cream cracker | D20: 3 | E20: =if(C20<>"", VLOOKUP(C20,' สรุปยอด 2'!A:D,4,0),0) -> 159 | F20: =E20*D20 -> 477
A21: 20 | B21: piggy | C21: สนามบิน NY 12 pc | D21: 3 | E21: 499 | F21: =E21*D21 -> 1497
A22: 21 | B22: piggy | C22: สนามบิน potato farm red | D22: 2 | E22: =if(C22<>"", VLOOKUP(C22,' สรุปยอด 2'!A:D,4,0),0) -> 339 | F22: =E22*D22 -> 678
A23: 23 | B23: piggy | C23: สนามบิน shiroi | D23: 1 | E23: 299 | F23: =E23*D23 -> 299
A24: 24 | B24: piggy | C24: ฮาดะทองใสแถบแดง (ขวด) | D24: 3 | E24: =if(C24<>"", VLOOKUP(C24,' สรุปยอด 2'!A:D,4,0),0) -> 275 | F24: =E24*D24 -> 825
A25: 25 | B25: piggy | C25: ฮาดะน้ำเงินแถบขาว (ขวด) | D25: 1 | E25: =if(C25<>"", VLOOKUP(C25,' สรุปยอด 2'!A:D,4,0),0) -> 275 | F25: =E25*D25 -> 275
A26: 26 | B26: bell | C26: ฮาดะแดงแถบขาว (ขวด) | D26: 1 | E26: =if(C26<>"", VLOOKUP(C26,' สรุปยอด 2'!A:D,4,0),0) -> 305 | F26: =E26*D26 -> 305
A27: 27 | B27: nuch | C27: Lip dhc ฟ้า | D27: 2 | E27: =if(C27<>"", VLOOKUP(C27,' สรุปยอด 2'!A:D,4,0),0) -> 239 | F27: =E27*D27 -> 478
A28: 28 | B28: nuch | C28: Lip dhc ปกติ | D28: 2 | E28: =if(C28<>"", VLOOKUP(C28,' สรุปยอด 2'!A:D,4,0),0) -> 179 | F28: =E28*D28 -> 358
A29: 29 | B29: nuch | C29: Lip dhc เทา | D29: 1 | E29: =if(C29<>"", VLOOKUP(C29,' สรุปยอด 2'!A:D,4,0),0) -> 190 | F29: =E29*D29 -> 190
A30: 30 | B30: tingting | C30: Lip dhc หน้ายิ้ม | D30: 1 | E30: =if(C30<>"", VLOOKUP(C30,' สรุปยอด 2'!A:D,4,0),0) -> 179 | F30: =E30*D30 -> 179
A31: 31 | B31: JR | C31: elixir sleeping brightening | D31: 1 | E31: =if(C31<>"", VLOOKUP(C31,' สรุปยอด 2'!A:D,4,0),0) -> 849 | F31: =E31*D31 -> 849
A32: 32 | B32: JR | C32: canmake fit glow cushion 01 | D32: 1 | E32: =if(C32<>"", VLOOKUP(C32,' สรุปยอด 2'!A:D,4,0),0) -> 429 | F32: =E32*D32 -> 429
A33: 33 | B33: JR | C33: elixir กันแดด brightening | D33: 1 | E33: =if(C33<>"", VLOOKUP(C33,' สรุปยอด 2'!A:D,4,0),0) -> 849 | F33: =E33*D33 -> 849
A34: 34 | B34: JR | C34: canmake ไฮไลท์ 02 | D34: 1 | E34: =if(C34<>"", VLOOKUP(C34,' สรุปยอด 2'!A:D,4,0),0) -> 179 | F34: =E34*D34 -> 179
A35: 35 | B35: ชมพู | C35: canmake ไฮไลท์ 03 | D35: 1 | E35: =if(C35<>"", VLOOKUP(C35,' สรุปยอด 2'!A:D,4,0),0) -> 179 | F35: =E35*D35 -> 179
... A214: 215 | B214: yui | C214: ถุง shopping 3 | D214: 3 | E214: =if(C214<>"", VLOOKUP(C214,' สรุปยอด 2'!A:D,4,0),0) -> 579 | F214: =E214*D214 -> 1737
A215: 216 | B215: geda | C215: รองเท้า gu | D215: 1 | E215: =if(C215<>"", VLOOKUP(C215,' สรุปยอด 2'!A:D,4,0),0) -> 849 | F215: =E215*D214 -> 2547
A216: 217 | B216: geda | C216: กาชาครัวซอง | D216: 7 | E216: =if(C216<>"", VLOOKUP(C216,' สรุปยอด 2'!A:D,4,0),0) -> 85 | F216: =E216*D216 -> 595
A217: 218 | B217: geda | C217: กาชา x sanrio | D217: 1 | E217: =if(C217<>"", VLOOKUP(C217,' สรุปยอด 2'!A:D,4,0),0) -> 115 | F217: =E217*D217 -> 115
A218: 219 | B218: geda | C218: จาน mofu | D218: 1 | E218: =if(C218<>"", VLOOKUP(C218,' สรุปยอด 2'!A:D,4,0),0) -> 199 | F218: =E218*D218 -> 199
A219: 220 | B219: geda | C219: quality ขาว | D219: 1 | E219: =if(C219<>"", VLOOKUP(C219,' สรุปยอด 2'!A:D,4,0),0) -> 205 | F219: =E219*D219 -> 205
A220: 221 | B220: geda | C220: quality ม่วง | D220: 1 | E220: =if(C220<>"", VLOOKUP(C220,' สรุปยอด 2'!A:D,4,0),0) -> 205 | F220: =E220*D220 -> 205
A221: 222 | B221: geda | C221: quality แดง | D221: 1 | E221: =if(C221<>"", VLOOKUP(C221,' สรุปยอด 2'!A:D,4,0),0) -> 205 | F221: =E221*D221 -> 205
A222: 223 | B222: waran | C222: daiso หูรูด kirby | D222: 1 | E222: =if(C222<>"", VLOOKUP(C222,' สรุปยอด 2'!A:D,4,0),0) -> 59 | F222: =E222*D222 -> 59
A223: 224 | B223: bp | C223: dior lipglow 001 | D223: 1 | E223: =if(C223<>"", VLOOKUP(C223,' สรุปยอด 2'!A:D,4,0),0) -> 1190 | F223: =E223*D223 -> 1190
A224: 225 | B224: pomme | C224: เสื้อ mancity gu | D224: 1 | E224: =if(C224<>"", VLOOKUP(C224,' สรุปยอด 2'!A:D,4,0),0) -> 549 | F224: =E224*D224 -> 549
...

Sheet ชีต3
B1: item | C1: amount | D1: price | E1: total
A2: 1 | B2: 7-11 ถั่วฟ้า | C2: 30 | D2: 49 | E2: =C2*D2 -> 1470
A3: 2 | B3: matcha cream cracker | C3: 3 | D3: 159 | E3: =C3*D3 -> 477
A4: 3 | B4: สนามบิน NY 12 pc | C4: 3 | D4: 499 | E4: =C4*D4 -> 1497
A5: 4 | B5: สนามบิน potato farm red | C5: 2 | D5: 339 | E5: =C5*D5 -> 678
A6: 5 | B6: สนามบิน shiroi | C6: 1 | D6: 299 | E6: =C6*D6 -> 299
A7: 6 | B7: ฮาดะทองใสแถบแดง (ขวด) | C7: 3 | D7: 275 | E7: =C7*D7 -> 825
A8: 7 | B8: ฮาดะน้ำเงินแถบขาว (ขวด) | C8: 1 | D8: 275 | E8: =C8*D8 -> 275
A9: 8 | B9: ขนมจิ้งจอก | C9: 2 | D9: 139 | E9: =C9*D9 -> 278
A10: 9 | B10: samidori | C10: 1 | D10: 419 | E10: =C10*D10 -> 419
A11: 10 | B11: kitkat matcha choc | C11: 1 | D11: 99 | E11: =C11*D11 -> 99
A12: 11 | B12: kitkat matcha | C12: 1 | D12: 99 | E12: =C12*D12 -> 99
A13: 12 | B13: kitkat strawberry | C13: 1 | D13: 99 | E13: =C13*D13 -> 99
... A45: 44 | B45: ตุ๊กตา mofu strawberry | C45: 1 | D45: 799 | E45: =C45*D45 -> 799
B46: Total | E46: =SUM(E2:E45) -> 26162

Sheet  สรุปยอด 2
A1: รายการสินค้า | B1: รูป | C1: จำนวนรวม | D1: ราคา (บาท) | E1: ซื้อไปแล้วเท่าไหร่ | F1: เหลือ
A2: {=UNIQUE('Japan 2'!C2:C748)} -> birken boston mocha 42 | C2: =SUMIF('Japan 2'!C2:C748,A2,'Japan 2'!D2:D748) -> 0 | D2: 5690 | F2: 0
A3: face mask medicube ชมพู | C3: =SUMIF('Japan 2'!C3:C748,A3,'Japan 2'!D3:D748) -> 5 | D3: 219 | F3: 0
A4: kose gluta bomb ชมพู | C4: =SUMIF('Japan 2'!C4:C748,A4,'Japan 2'!D4:D748) -> 1 | D4: 175 | F4: 0
A5: ฮาดะทองใสแถบแดง (ขวด) | C5: =SUMIF('Japan 2'!C5:C749,A5,'Japan 2'!D5:D749) -> 8 | D5: 275 | F5: 0
A6: medicube pro x2 pink | C6: =SUMIF('Japan 2'!C6:C748,A6,'Japan 2'!D6:D748) -> 3 | D6: 7490 | E6: 3 | F6: 0
A7: ฮาดะทองใสแถบแดง (รีฟิล) | C7: =SUMIF('Japan 2'!C7:C748,A7,'Japan 2'!D7:D748) -> 1 | D7: 259 | F7: 0
A8: urea cream กระปุก | C8: =SUMIF('Japan 2'!C8:C748,A8,'Japan 2'!D8:D748) -> 2 | D8: 199 | F8: 0
A9: มาส์กข้าว | C9: =SUMIF('Japan 2'!C9:C748,A9,'Japan 2'!D9:D748) -> 3 | D9: 195 | F9: 0
A10: 7-11 แซนวิสส้ม | C10: =SUMIF('Japan 2'!C10:C748,A10,'Japan 2'!D10:D748) -> 17 | D10: 85 | F10: 0
A11: 7-11 ลิ้นแมวไวท์ | C11: =SUMIF('Japan 2'!C11:C748,A11,'Japan 2'!D11:D748) -> 2 | D11: 65 | F11: 0
A12: Dior forever glow luminizer limited edition | C12: =SUMIF('Japan 2'!C12:C748,A12,'Japan 2'!D12:D748) -> 0 | D12: 2190 | F12: 0
A13: Arc'teryx s-m | C13: =SUMIF('Japan 2'!C13:C748,A13,'Japan 2'!D13:D748) -> 0 | D13: 1150 | F13: 0
A14: มาส์ก PDC red | C14: =SUMIF('Japan 2'!C14:C748,A14,'Japan 2'!D14:D748) -> 1 | D14: 195 | F14: 0
A15: 7-11 ถั่วฟ้า | C15: =SUMIF('Japan 2'!C15:C748,A15,'Japan 2'!D15:D748) -> 30 | D15: 49 | F15: 0
A16: matcha cream cracker | C16: =SUMIF('Japan 2'!C16:C748,A16,'Japan 2'!D16:D748) -> 3 | D16: 159 | E16: 3 | F16: 0
A17: สนามบิน NY 12 pc | C17: =SUMIF('Japan 2'!C17:C748,A17,'Japan 2'!D17:D748) -> 3 | D17: 349 | F17: 0
A18: สนามบิน potato farm red | C18: =SUMIF('Japan 2'!C18:C748,A18,'Japan 2'!D18:D748) -> 2 | D18: 339 | F18: 0
A19: สนามบิน shiroi | C19: =SUMIF('Japan 2'!C19:C748,A19,'Japan 2'!D19:D748) -> 1 | D19: 279 | F19: 0
A20: ฮาดะน้ำเงินแถบขาว (ขวด) | C20: =SUMIF('Japan 2'!C20:C748,A20,'Japan 2'!D20:D748) -> 2 | D20: 275 | F20: 0
A21: ฮาดะแดงแถบขาว (ขวด) | C21: =SUMIF('Japan 2'!C21:C748,A21,'Japan 2'!D21:D748) -> 3 | D21: 305 | F21: 0
A22: Lip dhc ฟ้า | C22: =SUMIF('Japan 2'!C22:C748,A22,'Japan 2'!D22:D748) -> 2 | D22: 239 | F22: 0
A23: Lip dhc ปกติ | C23: =SUMIF('Japan 2'!C23:C748,A23,'Japan 2'!D23:D748) -> 3 | D23: 179 | F23: 0
A24: Lip dhc เทา | C24: =SUMIF('Japan 2'!C23:C748,A24,'Japan 2'!D23:D748) -> 1 | D24: 190 | F24: 0
A25: Lip dhc หน้ายิ้ม | C25: =SUMIF('Japan 2'!C24:C748,A25,'Japan 2'!D24:D748) -> 1 | D25: 179 | F25: 0
A26: elixir sleeping brightening | C26: =SUMIF('Japan 2'!C25:C748,A26,'Japan 2'!D25:D748) -> 1 | D26: 849 | F26: 0
A27: canmake fit glow cushion 01 | C27: =SUMIF('Japan 2'!C26:C748,A27,'Japan 2'!D26:D748) -> 1 | D27: 429 | F27: 0
A28: elixir กันแดด brightening | C28: =SUMIF('Japan 2'!C27:C748,A28,'Japan 2'!D27:D748) -> 1 | D28: 849 | F28: 0
A29: canmake ไฮไลท์ 02 | C29: =SUMIF('Japan 2'!C28:C748,A29,'Japan 2'!D28:D748) -> 1 | D29: 179 | F29: 0
A30: canmake ไฮไลท์ 03 | C30: =SUMIF('Japan 2'!C28:C748,A30,'Japan 2'!D28:D748) -> 1 | D30: 179 | F30: 0
A31: หยดส้วมชมพู | C31: =SUMIF('Japan 2'!C30:C748,A31,'Japan 2'!D30:D748) -> 2 | D31: 99 | F31: 0
A32: mask anua green | C32: =SUMIF('Japan 2'!C31:C748,A32,'Japan 2'!D31:D748) -> 1 | D32: 209 | F32: 0
A33: mask anua blue | C33: =SUMIF('Japan 2'!C32:C748,A33,'Japan 2'!D32:D748) -> 1 | D33: 209 | F33: 0
A34: maputi สบู่ล้าง | C34: =SUMIF('Japan 2'!C33:C748,A34,'Japan 2'!D33:D748) -> 1 | F34: 0
A35: น้ำตบ C แถบแดง | C35: =SUMIF('Japan 2'!C34:C748,A35,'Japan 2'!D34:D748) -> 1 | D35: 289 | F35: 0
A36: ฮาดะแดงแถบขาว (รีฟิล) | C36: =SUMIF('Japan 2'!C35:C748,A36,'Japan 2'!D35:D748) -> 1 | D36: 279 | F36: 0
A37: Elixir กันแดด tone up | C37: =SUMIF('Japan 2'!C36:C748,A37,'Japan 2'!D36:D748) -> 2 | D37: 799 | F37: 0
A38: dior backstage palette 02 | C38: =SUMIF('Japan 2'!C37:C748,A38,'Japan 2'!D37:D748) -> 1 | D38: 1650 | E38: 1 | F38: 0
A39: 7-11 แซนวิสฟ้า | C39: =SUMIF('Japan 2'!C38:C748,A39,'Japan 2'!D38:D748) -> 10 | D39: 85 | F39: 0
A40: fino | C40: =SUMIF('Japan 2'!C39:C748,A40,'Japan 2'!D39:D748) -> 5 | D40: 249 | F40: 0
...

Sheet รวมยอดลูกค้า
A1: Checklist | C1: =COUNTA(C3:C950) -> 75 | D1: =sum(D3:D953) -> 161272 | E1: =sum(E3:E953) -> 529 | F1: =sum(F3:F953) -> 161801 | G1: =SUMIF(G3:G953, "โอนแล้ว", F3:F953) -> 5155
C2: ชื่อลูกค้า | D2: รวมยอด | E2: ค่าส่ง | F2: รวมทั้งหมด | G2: โอน | H2: หมายเหตุ | I2: ที่อยู่จัดส่ง | J2: รวมเงินได้ | K2: =sum(F3:F953) -> 161801 | L2: =0.18*K2 -> 29124.18
A3: FALSE | B3: 1 | C3: {=unique('Japan 2'!B2:B953)} -> Joyya | D3: =sumif('Japan 2'!B:B,C3,'Japan 2'!F:F) -> 0 | F3: =D3+E3 -> 0
A4: FALSE | B4: 2 | C4: plearn | D4: =sumif('Japan 2'!B:B,C4,'Japan 2'!F:F) -> 2388 | F4: =D4+E4 -> 2388
A5: FALSE | B5: 3 | C5: may | D5: =sumif('Japan 2'!B:B,C5,'Japan 2'!F:F) -> 615 | F5: =D5+E5 -> 615
A6: FALSE | B6: 4 | C6: sukwasa | D6: =sumif('Japan 2'!B:B,C6,'Japan 2'!F:F) -> 7490 | F6: =D6+E6 -> 7490
A7: FALSE | B7: 5 | C7: fonjinda | D7: =sumif('Japan 2'!B:B,C7,'Japan 2'!F:F) -> 627 | F7: =D7+E7 -> 627
A8: FALSE | B8: 6 | C8: จอมโหด | D8: =sumif('Japan 2'!B:B,C8,'Japan 2'!F:F) -> 275 | E8: 50 | F8: =D8+E8 -> 325 | G8: ยังไม่โอน
A9: FALSE | B9: 7 | C9: Mt | D9: =sumif('Japan 2'!B:B,C9,'Japan 2'!F:F) -> 1272 | F9: =D9+E9 -> 1272
A10: FALSE | B10: 8 | C10: Pomme | D10: =sumif('Japan 2'!B:B,C10,'Japan 2'!F:F) -> 3355 | F10: =D10+E10 -> 3355
A11: FALSE | B11: 9 | C11: geda | D11: =sumif('Japan 2'!B:B,C11,'Japan 2'!F:F) -> 9488 | F11: =D11+E11 -> 9488
A12: FALSE | B12: 10 | C12: tingting | D12: =sumif('Japan 2'!B:B,C12,'Japan 2'!F:F) -> 1873 | F12: =D12+E12 -> 1873
A13: FALSE | B13: 11 | C13: waran | D13: 758 | F13: =D13+E13 -> 758
A14: FALSE | B14: 12 | C14: piggy | D14: =sumif('Japan 2'!B:B,C14,'Japan 2'!F:F) -> 12268 | F14: =D14+E14 -> 12268
A15: FALSE | B15: 13 | C15: bell | D15: =sumif('Japan 2'!B:B,C15,'Japan 2'!F:F) -> 305 | F15: =D15+E15 -> 305
A16: FALSE | B16: 14 | C16: nuch | D16: =sumif('Japan 2'!B:B,C16,'Japan 2'!F:F) -> 2223 | F16: =D16+E16 -> 2223
A17: FALSE | B17: 15 | C17: JR | D17: =sumif('Japan 2'!B:B,C17,'Japan 2'!F:F) -> 2780 | F17: =D17+E17 -> 2780
A18: FALSE | B18: 16 | C18: ชมพู | D18: =sumif('Japan 2'!B:B,C18,'Japan 2'!F:F) -> 473 | F18: =D18+E18 -> 473
A19: FALSE | B19: 17 | C19: Airrr | D19: =sumif('Japan 2'!B:B,C19,'Japan 2'!F:F) -> 418 | F19: =D19+E19 -> 418
A20: FALSE | B20: 18 | C20: Mint | D20: =sumif('Japan 2'!B:B,C20,'Japan 2'!F:F) -> 579 | F20: =D20+E20 -> 579
A21: FALSE | B21: 19 | C21: bow | D21: =sumif('Japan 2'!B:B,C21,'Japan 2'!F:F) -> 6173 | F21: =D21+E21 -> 6173
A22: FALSE | B22: 20 | C22: แนน | D22: =sumif('Japan 2'!B:B,C22,'Japan 2'!F:F) -> 6404 | F22: =D22+E22 -> 6404
A23: FALSE | B23: 21 | C23: meiji | D23: =sumif('Japan 2'!B:B,C23,'Japan 2'!F:F) -> 478 | F23: =D23+E23 -> 478
A24: FALSE | B24: 22 | C24: aluli | D24: =sumif('Japan 2'!B:B,C24,'Japan 2'!F:F) -> 7490 | F24: =D24+E24 -> 7490
A25: FALSE | B25: 23 | C25: june | D25: =sumif('Japan 2'!B:B,C25,'Japan 2'!F:F) -> 1650 | F25: =D25+E25 -> 1650
... A29: FALSE | B29: 27 | C29: bencho | D29: =sumif('Japan 2'!B:B,C29,'Japan 2'!F:F) -> 7727 | F29: =D29+E29 -> 7727
A30: FALSE | B30: 28 | C30: nnayne | D30: =sumif('Japan 2'!B:B,C30,'Japan 2'!F:F) -> 833 | E30: 39 | F30: =D30+E30 -> 872 | G30: ยังไม่โอน
A31: FALSE | B31: 29 | C31: ebapp | D31: =sumif('Japan 2'!B:B,C31,'Japan 2'!F:F) -> 548 | F31: =D31+E31 -> 548
A32: FALSE | B32: 30 | C32: pookie | D32: =sumif('Japan 2'!B:B,C32,'Japan 2'!F:F) -> 8514 | E32: 39 | F32: =D32+E32 -> 8553 | G32: ยังไม่โอน
A33: FALSE | B33: 31 | C33: dada | D33: =sumif('Japan 2'!B:B,C33,'Japan 2'!F:F) -> 679 | F33: =D33+E33 -> 679
A34: FALSE | B34: 32 | C34: bobelle | D34: =sumif('Japan 2'!B:B,C34,'Japan 2'!F:F) -> 2434 | F34: =D34+E34 -> 2434
A35: FALSE | B35: 33 | C35: toeii | D35: =sumif('Japan 2'!B:B,C35,'Japan 2'!F:F) -> 1371 | F35: =D35+E35 -> 1371
A36: FALSE | B36: 34 | C36: maiiz | D36: =sumif('Japan 2'!B:B,C36,'Japan 2'!F:F) -> 8436 | F36: =D36+E36 -> 8436
A37: FALSE | B37: 35 | C37: กระต่าย | D37: =sumif('Japan 2'!B:B,C37,'Japan 2'!F:F) -> 1105 | E37: 39 | F37: =D37+E37 -> 1144 | G37: ยังไม่โอน
A38: FALSE | B38: 36 | C38: aommy | D38: =sumif('Japan 2'!B:B,C38,'Japan 2'!F:F) -> 659 | E38: 39 | F38: =D38+E38 -> 698 | G38: ยังไม่โอน
A39: FALSE | B39: 37 | C39: mint | D39: =sumif('Japan 2'!B:B,C39,'Japan 2'!F:F) -> 579 | F39: =D39+E39 -> 579
A40: FALSE | B40: 38 | C40: Bee | D40: =sumif('Japan 2'!B:B,C40,'Japan 2'!F:F) -> 1750 | F40: =D40+E40 -> 1750
A41: FALSE | B41: 39 | C41: Aom | D41: =sumif('Japan 2'!B:B,C41,'Japan 2'!F:F) -> 1598 | F41: =D41+E41 -> 1598
A42: FALSE | B42: 40 | C42: ปอย | D42: =sumif('Japan 2'!B:B,C42,'Japan 2'!F:F) -> 99 | F42: =D42+E42 -> 99
A43: FALSE | B43: 41 | C43: your | D43: =sumif('Japan 2'!B:B,C43,'Japan 2'!F:F) -> 1547 | E43: 39 | F43: =D43+E43 -> 1586
...
